File: deploy/examples/gaaspn_xrr.xrdml
<?xml version="1.0" encoding="UTF-8"?>
<xrdMeasurements status="Completed" xmlns="http://www.xrdml.com/XRDMeasurement/1.5" xmlns:xsi="http://www.w3.org/2001/XMLSchema-instance" xsi:schemaLocation="http://www.xrdml.com/XRDMeasurement/1.5 http://www.xrdml.com/XRDMeasurement/1.5/XRDMeasurement.xsd">
  <xrdMeasurement status="Completed" measurementType="Scan">
    <scan status="Completed" appendNumber="0" scanAxis="Omega-2Theta" mode="Continuous">
      <header>
        <startTimeStamp>2013-06-03T11:44:00+03:00</startTimeStamp>
        <source>
          <applicationSoftware version="0.1">None</applicationSoftware>
        </source>
      </header>
      <dataPoints>
        <positions axis="2Theta" unit="deg">
          <startPosition>0.00100</startPosition>
          <endPosition>3.99700</endPosition>
        </positions>
        <positions axis="Omega" unit="deg">
          <startPosition>0.00050</startPosition>
          <endPosition>1.99850</endPosition>
        </positions>
        <positions axis="Phi" unit="deg">
          <commonPosition>0.0</commonPosition>
        </positions>
        <positions axis="Chi" unit="deg">
          <commonPosition>0.000</commonPosition>
        </positions>
        <positions axis="X" unit="mm">
          <commonPosition>0.00</commonPosition>
        </positions>
        <positions axis="Y" unit="mm">
          <commonPosition>0.00</commonPosition>
        </positions>
        <commonCountingTime unit="seconds">2.00</commonCountingTime>
        <intensities unit="counts">
          10926400
          10643360
          9664160
          8361600
          6826400
          5487520
          4236480
          3158400
          2228000
          1448960
          855040
          546311
          319374
          202500
          140992
          110182
          93957
          82792
          76117
          70317
          65882
          62052
          58312
          56056
          53674
          51737
          50738
          49395
          48689
          47761
          46918
          46969
          46255
          46582
          46479
          47175
          47368
          47984
          48041
          48521
          48950
          50182
          50968
          51207
          51265
          52479
          53214
          53555
          54164
          54427
          56057
          56261
          56710
          57586
          58061
          58544
          59307
          59651
          59932
          60523
          61199
          61955
          62624
          62810
          63933
          63659
          64746
          65357
          65680
          66472
          66951
          67353
          68448
          68321
          68853
          69293
          69883
          70808
          70628
          70448
          71768
          72393
          72084
          72642
          73162
          73313
          73764
          73822
          74302
          74529
          74786
          75825
          75879
          75854
          76154
          76517
          77122
          76729
          77862
          77426
          77302
          78676
          78079
          78340
          78552
          79259
          79434
          79470
          79761
          80181
          79870
          80421
          80768
          80279
          80494
          80501
          80827
          80937
          81250
          81184
          81361
          80751
          80609
          80376
          79999
          79431
          78027
          77720
          76097
          74385
          71900
          69059
          66017
          62577
          59679
          56024
          52271
          49241
          46168
          43743
          40672
          37643
          35446
          32998
          30626
          28201
          25900
          24001
          22280
          20303
          18441
          17055
          15632
          14200
          12861
          11741
          10745
          10046
          9184
          8491
          7921
          7160
          6700
          5904
          5502
          5191
          4716
          4453
          4221
          3977
          3770
          3546
          3535
          3132
          3170
          3001
          2953
          2806
          2784
          2692
          2588
          2545
          2537
          2509
          2417
          2332
          2354
          2314
          2293
          2149
          2143
          2091
          2137
          2103
          2020
          1960
          1847
          1863
          1803
          1827
          1726
          1731
          1651
          1650
          1604
          1575
          1443
          1442
          1362
          1356
          1326
          1264
          1268
          1209
          1211
          1142
          1097
          1032
          953
          964
          976
          922
          919
          869
          845
          809
          755
          755
          636
          677
          630
          578
          584
          549
          605
          517
          519
          485
          522
          480
          467
          463
          433
          410
          409
          368
          408
          361
          380
          341
          326
          337
          328
          297
          305
          298
          272
          297
          285
          254
          286
          234
          287
          266
          258
          254
          229
          238
          227
          260
          215
          216
          236
          235
          240
          245
          222
          194
          219
          210
          174
          201
          223
          238
          206
          219
          208
          190
          176
          205
          228
          172
          191
          189
          173
          171
          159
          168
          197
          198
          151
          154
          161
          167
          146
          179
          143
          146
          128
          126
          132
          147
          109
          139
          124
          110
          106
          119
          97
          105
          88
          109
          80
          94
          96
          95
          97
          90
          74
          77
          69
          71
          64
          64
          75
          62
          67
          43
          53
          45
          67
          53
          48
          58
          31
          49
          43
          44
          48
          54
          48
          27
          44
          42
          31
          42
          37
          36
          46
          46
          36
          39
          19
          47
          40
          37
          37
          43
          33
          42
          34
          39
          36
          37
          37
          35
          34
          19
          34
          37
          37
          39
          37
          29
          29
          28
          28
          32
          38
          38
          26
          30
          33
          31
          35
          34
          34
          49
          31
          32
          24
          24
          23
          21
          27
          24
          31
          32
          15
          21
          27
          13
          25
          14
          15
          27
          15
          20
          16
          14
          19
          14
          21
          8
          19
          22
          15
          14
          10
          13
          13
          11
          14
          17
          15
          10
          5
          12
          6
          11
          5
          12
          9
          9
          4
          7
          5
          8
          8
          6
          5
          9
          11
          5
          7
          6
          13
          4
          9
          4
          5
          3
          8
          6
          5
          6
          7
          7
          8
          6
          2
          4
          4
          4
          4
          8
          5
          8
          7
          3
          7
          12
          7
          6
          10
          7
          3
          10
          5
          7
          9
          6
          3
          9
          2
          8
          8
          2
          8
          9
          6
          2
          9
          6
          4
          8
          10
          5
          9
          8
          3
          8
          3
          1
          7
          7
          3
          6
          1
          5
          5
          5
          5
          1
          3
          4
          1
          4
          1
          2
          5
          4
          1
          2
          1
          5
          2
          3
          5
          3
          5
          1
          1
          5
          3
          2
          3
          2
          3
          1
          1
          2
          1
          0
          0
          2
          3
          1
          2
          0
          1
          1
          0
          1
          1
          1
          3
          1
          2
          2
          1
          3
          2
          3
          1
          3
          3
          6
          0
          2
          2
          0
          2
          1
          2
          2
          2
          2
          1
          1
          1
          1
          1
          2
          1
          2
          1
          1
          3
          0
          5
          3
          0
          1
          1
          4
          2
          1
          0
          2
          3
          0
          0
          1
          0
          2
          1
          1
          1
          0
          2
          2
          3
          1
          4
          1
          1
          3
          3
          0
          4
          3
          3
          5
          2
          1
          0
          2
          2
          1
          2
          1
          5
          1
          3
          2
          0
          0
          3
          3
          3
          2
          4
          1
          3
          1
          2
          1
          2
          3
          0
          4
          3
          2
          1
          1
          0
          2
          2
          1
          3
          1
          2
          1
          0
          0
          1
          1
          2
          3
          2
          3
          2
          2
          2
          1
          2
          3
          2
          2
          2
          5
          2
          2
          1
          0
          1
          1
          2
          2
          3
          1
          1
          0
          0
          3
          1
          1
          3
          2
          4
          3
          3
          1
          0
          2
          2
          3
          0
          3
          3
          3
          0
          0
          0
          5
          3
          2
          4
          1
          1
          4
          0
          2
          0
          4
          2
          0
          2
          2
          2
          5
          0
          2
          4
          1
          2
          1
          2
          0
          2
          3
          4
          4
          3
          3
          0
          2
          1
          3
          4
          1
          2
          2
          4
          2
          4
          2
          5
          2
          0
          1
          2
          1
          2
          4
          2
          3
          0
          0
          0
          0
          6
          5
          2
          0
          3
          1
          1
          2
          0
          2
          2
          3
          0
          4
          2
          3
          2
          1
          1
          2
          2
          1
          3
          1
          3
          1
          1
          3
          1
          3
          4
          2
          0
          2
          3
          3
          6
          2
          3
          3
          3
          1
          0
          3
          3
          2
          1
          2
          2
          6
          5
          1
          0
          2
          1
          1
          3
          4
          1
          2
          4
          3
          6
          1
          2
          1
          3
          0
          2
          4
          4
          3
          1
          3
          3
          2
          7
          3
          3
          2
          4
          0
          2
          2
          3
          2
          1
          1
          2
          2
          4
          1
          1
          3
          4
          1
          6
          3
          2
          5
          3
          0
          3
          2
          5
          4
          3
          1
          1
          2
          0
          3
          1
          3
          2
          1
          2
          0
          1
          1
          1
          1
          2
          0
          4
          2
          4
          0
          4
          1
          1
          3
          2
          0
          4
          1
          5
          1
          3
          2
          5
          3
          5
          2
          1
          1
          3
          2
          5
          3
          3
          4
          2
          0
          1
          1
          3
          2
          7
          1
          1
          3
          3
          1
          1
          3
          2
          1
          2
          3
          2
          1
          0
          3
          2
          2
          3
          2
          2
          1
          2
          1
          1
          3
          1
          1
          2
          2
          3
          3
          2
          0
          0
          0
          3
          0
          3
          1
          1
          3
          4
          5
          2
          5
          3
          1
          3
          3
          2
          3
          2
          1
          2
          1
          2
          4
          4
          4
        </intensities>
      </dataPoints>
    </scan>
  </xrdMeasurement>
</xrdMeasurements>