File: deploy/examples/xrr003.xrdml
<?xml version="1.0" encoding="UTF-8"?>
<xrdMeasurements status="Completed" xmlns="http://www.xrdml.com/XRDMeasurement/1.5" xmlns:xsi="http://www.w3.org/2001/XMLSchema-instance" xsi:schemaLocation="http://www.xrdml.com/XRDMeasurement/1.5 http://www.xrdml.com/XRDMeasurement/1.5/XRDMeasurement.xsd">
  <xrdMeasurement status="Completed" measurementType="Scan">
    <scan status="Completed" appendNumber="0" scanAxis="Omega-2Theta" mode="Continuous">
      <header>
        <startTimeStamp>2014-06-25T16:52:00+03:00</startTimeStamp>
        <source>
          <applicationSoftware version="0.1">None</applicationSoftware>
        </source>
      </header>
      <dataPoints>
        <positions axis="2Theta" unit="deg">
          <startPosition>0.00100</startPosition>
          <endPosition>3.99700</endPosition>
        </positions>
        <positions axis="Omega" unit="deg">
          <startPosition>0.00050</startPosition>
          <endPosition>1.99850</endPosition>
        </positions>
        <positions axis="Phi" unit="deg">
          <commonPosition>-0.7</commonPosition>
        </positions>
        <positions axis="Chi" unit="deg">
          <commonPosition>0.040</commonPosition>
        </positions>
        <positions axis="X" unit="mm">
          <commonPosition>0.00</commonPosition>
        </positions>
        <positions axis="Y" unit="mm">
          <commonPosition>0.50</commonPosition>
        </positions>
        <commonCountingTime unit="seconds">2.00</commonCountingTime>
        <intensities unit="counts">
          2373234.0000
          2727276.0000
          2840802.0000
          2747268.0000
          2494002.0000
          2097528.0000
          1751748.0000
          1372920.0000
          1047438.0000
          732360.0000
          493068.0000
          306306.0000
          175547.5000
          115466.0000
          83314.5000
          67706.0000
          59416.0000
          55142.0000
          52562.0000
          50123.0000
          48565.5000
          47469.0000
          46805.5000
          46341.0000
          46162.5000
          46326.5000
          46363.0000
          46518.0000
          47301.0000
          47940.5000
          48902.0000
          49439.5000
          50459.0000
          51210.5000
          52096.5000
          53457.0000
          54451.0000
          55479.0000
          56603.0000
          57787.5000
          58722.5000
          59990.5000
          61390.0000
          62594.0000
          63777.5000
          65038.0000
          66373.5000
          67919.0000
          69032.0000
          70124.5000
          70969.0000
          72864.5000
          73817.5000
          75467.0000
          76661.0000
          77768.5000
          79125.5000
          80287.5000
          81516.0000
          82666.5000
          83943.5000
          85213.5000
          86455.5000
          87447.5000
          89025.0000
          90487.0000
          91507.5000
          93325.5000
          94113.0000
          95304.5000
          96519.5000
          97988.5000
          99197.5000
          100184.0000
          101197.5000
          102485.5000
          104332.5000
          105109.5000
          106802.0000
          107850.0000
          108610.0000
          110344.5000
          111243.0000
          113055.5000
          114289.5000
          115803.0000
          116542.5000
          118308.0000
          119218.0000
          120035.0000
          121840.5000
          122824.0000
          123687.0000
          124937.5000
          126607.0000
          127661.5000
          128462.0000
          128986.0000
          130339.5000
          131451.5000
          132259.5000
          133612.5000
          134618.5000
          135709.0000
          136639.0000
          136927.0000
          137631.5000
          139047.0000
          139671.5000
          140353.5000
          140873.0000
          141974.5000
          142646.5000
          143389.5000
          143664.5000
          144649.5000
          145032.5000
          145249.5000
          146087.5000
          146218.0000
          147021.0000
          147127.0000
          147316.5000
          147246.0000
          147581.0000
          147543.0000
          148224.0000
          147800.0000
          147497.5000
          148150.5000
          147118.0000
          147586.0000
          147204.0000
          146112.5000
          145234.5000
          144814.5000
          143200.5000
          141836.5000
          139921.5000
          137171.5000
          133932.5000
          129526.0000
          125247.0000
          120675.0000
          114727.0000
          108946.0000
          102615.5000
          96308.0000
          88258.5000
          81184.5000
          73508.5000
          66034.0000
          58796.0000
          51533.0000
          45287.0000
          39307.0000
          34183.5000
          29510.5000
          25811.5000
          22675.5000
          19847.0000
          18022.0000
          16377.5000
          15270.0000
          14541.5000
          13698.5000
          13517.0000
          12953.0000
          13025.0000
          12776.0000
          12799.5000
          12659.5000
          12702.0000
          12349.0000
          12155.0000
          12008.0000
          11705.5000
          11548.0000
          11298.0000
          10893.5000
          10468.0000
          10057.0000
          9737.5000
          9261.0000
          8997.5000
          8357.0000
          7936.0000
          7608.5000
          6953.0000
          6563.5000
          6190.0000
          5764.5000
          5303.5000
          5003.0000
          4674.0000
          4253.0000
          3988.5000
          3757.0000
          3500.5000
          3299.5000
          3045.0000
          2940.5000
          2798.0000
          2639.5000
          2625.5000
          2506.5000
          2432.5000
          2374.0000
          2342.0000
          2303.5000
          2254.5000
          2316.0000
          2312.0000
          2259.5000
          2242.5000
          2231.5000
          2315.0000
          2261.5000
          2288.5000
          2233.5000
          2245.5000
          2237.5000
          2236.0000
          2197.0000
          2180.5000
          2105.5000
          2134.0000
          2016.0000
          2035.5000
          1994.0000
          1995.5000
          1893.0000
          1858.5000
          1786.5000
          1687.5000
          1633.5000
          1529.5000
          1516.0000
          1487.0000
          1376.0000
          1345.5000
          1257.5000
          1204.5000
          1180.0000
          1083.0000
          1042.0000
          971.5000
          886.0000
          891.0000
          796.5000
          794.5000
          730.5000
          711.5000
          645.0000
          615.0000
          629.5000
          544.5000
          551.0000
          538.5000
          507.0000
          486.0000
          492.5000
          492.5000
          481.5000
          468.5000
          457.5000
          451.0000
          475.0000
          460.5000
          460.5000
          467.0000
          461.0000
          476.0000
          489.5000
          459.0000
          456.5000
          483.5000
          452.5000
          502.0000
          481.5000
          454.0000
          473.0000
          446.5000
          464.0000
          443.5000
          490.0000
          460.5000
          429.0000
          453.5000
          438.0000
          439.0000
          415.0000
          391.5000
          397.0000
          375.0000
          386.0000
          352.5000
          355.0000
          344.0000
          324.0000
          303.0000
          302.5000
          263.0000
          263.5000
          256.5000
          252.0000
          231.0000
          207.0000
          202.0000
          214.0000
          189.0000
          187.0000
          170.0000
          151.5000
          156.5000
          143.5000
          151.5000
          142.5000
          122.5000
          114.5000
          112.0000
          120.0000
          114.5000
          102.0000
          124.5000
          112.0000
          93.0000
          121.0000
          103.5000
          107.5000
          118.0000
          104.0000
          107.0000
          124.5000
          115.0000
          114.5000
          117.5000
          126.5000
          134.5000
          129.0000
          131.5000
          135.5000
          135.0000
          134.0000
          116.5000
          124.5000
          118.5000
          124.5000
          144.0000
          131.0000
          125.0000
          124.5000
          124.0000
          108.0000
          120.0000
          104.0000
          120.0000
          111.0000
          102.0000
          96.5000
          89.5000
          88.0000
          83.0000
          77.0000
          82.0000
          77.5000
          72.0000
          71.0000
          58.5000
          60.0000
          50.0000
          54.5000
          50.0000
          47.0000
          43.0000
          37.5000
          40.0000
          35.5000
          36.0000
          33.0000
          34.5000
          34.5000
          35.5000
          30.5000
          27.5000
          27.0000
          30.5000
          29.5000
          28.0000
          28.5000
          22.5000
          26.5000
          22.5000
          25.5000
          25.5000
          32.5000
          27.0000
          32.0000
          31.0000
          31.5000
          33.0000
          38.5000
          34.5000
          32.0000
          29.5000
          30.0000
          27.0000
          42.0000
          37.5000
          37.0000
          40.5000
          37.0000
          35.0000
          27.0000
          42.0000
          36.5000
          38.0000
          34.5000
          36.0000
          25.5000
          43.5000
          25.5000
          32.0000
          29.0000
          27.5000
          25.5000
          22.0000
          24.0000
          19.5000
          27.5000
          23.5000
          24.5000
          17.0000
          21.0000
          13.5000
          15.0000
          16.0000
          16.5000
          16.5000
          12.5000
          10.0000
          8.0000
          16.0000
          6.5000
          7.0000
          5.0000
          6.0000
          8.0000
          5.5000
          7.0000
          5.0000
          7.5000
          7.5000
          9.0000
          6.5000
          7.5000
          9.5000
          7.0000
          10.5000
          7.5000
          8.0000
          6.5000
          10.0000
          11.0000
          12.5000
          12.0000
          15.0000
          7.5000
          10.5000
          12.0000
          13.0000
          15.5000
          11.5000
          16.0000
          13.5000
          13.5000
          17.5000
          10.0000
          15.0000
          12.0000
          13.5000
          19.0000
          12.5000
          15.0000
          11.0000
          17.0000
          10.0000
          10.5000
          10.0000
          7.5000
          8.5000
          11.0000
          7.0000
          9.0000
          7.5000
          8.5000
          5.0000
          5.5000
          6.5000
          6.5000
          4.0000
          6.0000
          5.5000
          4.5000
          4.0000
          4.5000
          4.5000
          3.5000
          1.0000
          5.0000
          3.0000
          1.0000
          3.0000
          3.0000
          3.5000
          2.0000
          2.5000
          2.0000
          4.0000
          1.0000
          3.0000
          3.5000
          2.0000
          3.0000
          3.5000
          4.5000
          4.5000
          7.0000
          3.0000
          6.5000
          5.0000
          1.5000
          6.0000
          6.5000
          6.0000
          10.0000
          10.0000
          6.0000
          6.0000
          4.0000
          2.0000
          3.0000
          6.5000
          6.0000
          5.5000
          8.5000
          7.0000
          6.0000
          7.5000
          7.0000
          3.0000
          4.0000
          6.0000
          4.5000
          4.5000
          7.0000
          2.5000
          3.0000
          5.5000
          3.5000
          4.5000
          4.5000
          4.0000
          3.5000
          1.0000
          3.5000
          3.0000
          0.5000
          2.0000
          2.5000
          3.5000
          4.0000
          2.5000
          2.5000
          1.5000
          2.0000
          1.5000
          3.0000
          4.0000
          1.5000
          3.5000
          1.5000
          2.5000
          2.0000
          0.5000
          1.0000
          4.0000
          3.5000
          4.5000
          2.0000
          2.5000
          3.5000
          2.0000
          3.0000
          2.0000
          4.5000
          4.5000
          6.0000
          3.5000
          5.5000
          2.0000
          5.0000
          6.5000
          3.5000
          3.0000
          4.0000
          4.0000
          5.0000
          2.0000
          4.5000
          4.0000
          2.5000
          3.5000
          5.5000
          4.5000
          7.0000
          3.0000
          5.0000
          3.5000
          3.0000
          6.5000
          5.0000
          6.0000
          3.0000
          3.5000
          6.0000
          5.0000
          3.5000
          2.0000
          3.0000
          4.5000
          1.5000
          4.0000
          1.5000
          3.0000
          1.5000
          0.0000
          1.5000
          1.5000
          0.5000
          1.0000
          2.5000
          1.5000
          4.5000
          0.0000
          0.5000
          3.0000
          3.0000
          0.5000
          1.5000
          2.0000
          1.5000
          2.0000
          1.0000
          2.5000
          2.5000
          2.0000
          2.5000
          2.0000
          1.0000
          3.0000
          2.5000
          3.0000
          3.0000
          1.0000
          3.0000
          3.0000
          3.5000
          4.5000
          2.0000
          5.5000
          4.0000
          2.0000
          4.5000
          3.0000
          3.0000
          4.0000
          4.0000
          4.5000
          2.5000
          4.5000
          2.5000
          5.0000
          3.5000
          4.5000
          4.5000
          3.0000
          3.5000
          3.5000
          3.0000
          3.0000
          3.0000
          2.5000
          3.5000
          2.0000
          2.5000
          3.5000
          2.5000
          1.5000
          3.5000
          3.0000
          1.5000
          2.0000
          3.0000
          2.0000
          1.0000
          3.0000
          3.0000
          2.0000
          1.0000
          3.0000
          2.0000
          3.5000
          2.0000
          1.5000
          1.5000
          2.5000
          3.0000
          1.0000
          1.5000
          1.5000
          2.0000
          2.0000
          1.5000
          0.5000
          2.0000
          1.5000
          2.0000
          0.0000
          2.0000
          5.0000
          4.0000
          4.0000
          2.5000
          1.0000
          1.0000
          1.0000
          1.5000
          4.5000
          3.0000
          2.0000
          2.0000
          1.5000
          1.0000
          3.0000
          1.5000
          1.0000
          3.0000
          2.0000
          2.5000
          6.0000
          2.5000
          1.5000
          1.5000
          2.0000
          2.0000
          5.0000
          1.0000
          3.0000
          0.5000
          1.5000
          4.5000
          2.5000
          2.5000
          1.0000
          2.5000
          2.0000
          2.0000
          2.0000
          1.0000
          2.0000
          2.0000
          1.0000
          1.5000
          0.5000
          1.0000
          1.5000
          1.5000
          0.5000
          1.0000
          1.0000
          0.5000
          3.0000
          2.0000
          0.5000
          0.5000
          2.5000
          2.0000
          1.0000
          1.0000
          1.0000
          1.5000
          1.0000
          2.5000
          1.5000
          2.5000
          0.5000
          1.0000
          1.0000
          0.5000
          1.0000
          0.5000
          0.5000
          1.0000
          3.5000
          2.0000
          3.0000
          2.5000
          1.0000
          0.5000
          1.0000
          2.0000
          3.5000
          2.0000
          2.0000
          1.0000
          0.5000
          0.5000
          2.5000
          2.0000
          2.0000
          3.0000
          3.0000
          2.0000
          1.5000
          2.5000
          0.0000
          2.0000
          3.0000
          2.0000
          0.5000
          0.5000
          1.0000
          2.0000
          2.0000
          1.5000
          1.5000
          0.0000
          0.0000
          0.5000
          4.0000
          1.5000
          0.5000
          1.0000
          1.0000
          1.5000
          1.5000
          1.0000
          1.0000
          1.0000
          1.0000
          1.0000
          1.0000
          0.5000
          2.0000
          0.5000
          1.5000
          0.5000
          2.0000
          2.0000
          1.5000
          1.0000
          0.0000
          1.0000
          1.5000
          1.5000
          1.0000
          0.5000
          1.0000
          0.5000
          0.5000
          2.0000
          1.5000
          1.0000
          0.5000
          0.0000
          1.0000
          2.5000
          0.0000
          3.5000
          0.5000
          1.0000
          0.5000
          1.5000
          2.0000
          1.5000
          2.0000
          0.0000
          1.5000
          3.0000
          1.5000
          1.0000
          2.5000
          1.0000
          2.0000
          1.0000
          1.0000
          1.5000
          0.5000
          2.0000
          0.5000
          2.0000
          0.5000
          1.5000
          3.5000
          2.0000
          1.5000
          1.0000
          2.5000
          0.0000
          0.5000
          1.0000
          0.5000
          0.0000
          1.0000
          0.5000
          2.0000
          1.0000
          0.5000
          2.0000
          1.0000
          1.0000
          1.0000
          0.0000
          2.5000
          0.0000
          1.5000
          1.0000
          0.0000
          0.0000
          2.0000
          0.0000
          0.0000
          0.0000
          0.5000
          0.0000
          0.0000
          0.5000
          0.5000
          0.0000
          0.0000
          0.5000
          1.5000
          0.5000
          0.5000
          1.5000
          1.0000
          1.5000
          1.0000
          0.0000
          1.5000
          2.0000
          0.5000
          0.5000
          1.5000
          1.0000
          1.0000
          0.5000
          1.0000
          0.5000
          0.0000
          0.5000
          1.5000
          1.0000
          1.5000
          1.0000
          0.5000
          1.5000
          0.5000
          1.0000
          1.5000
          1.0000
          1.5000
          2.0000
          1.5000
          0.5000
          1.5000
          1.0000
          3.0000
          1.5000
          1.0000
          0.0000
          0.5000
          1.0000
          0.0000
          1.5000
          1.0000
          2.0000
          1.0000
          0.5000
          1.5000
          1.0000
          0.0000
          0.0000
          1.0000
          2.0000
          0.5000
          2.5000
          1.0000
          1.5000
        </intensities>
      </dataPoints>
    </scan>
  </xrdMeasurement>
</xrdMeasurements>